Workbook

Sheet Resumen Ejecutivo
B2: RESUMEN EJECUTIVO · JORNALEROS
B3: ="Período: "&CHOOSE(MONTH($D$4),"Enero","Febrero","Marzo","Abril","Mayo","Junio","Julio","Agosto","Septiembre","Octubre","Noviembre","Diciembre")&" "&YEAR($D$4)&" · Fuente: hojas Reporte y LIQUIDACION · Preparado por RR.HH."
C4: Mes del reporte (1er día): | D4: 46266 | E4: ← cambiar cada mes
C6: Personas contratadas | D6: Jornadas trabajadas | F6: Neto pactado total | J6: Costo prom. por jornada | L6: Jornadas prom. por persona
C7: =SUMPRODUCT((Reporte!$K$2:$K$1000<>"")/COUNTIF(Reporte!$E$2:$E$1000,Reporte!$E$2:$E$1000&"")) | D7: =SUMPRODUCT((Reporte!$K$2:$K$1000<>"")*Reporte!$H$2:$H$1000) | F7: =SUMPRODUCT((Reporte!$K$2:$K$1000<>"")*Reporte!$J$2:$J$1000) | J7: =IFERROR(F7/D7,0) | L7: =IFERROR(D7/C7,0)
C9: Contratos / registros | D9: Total bruto liquidado | F9: Aportes (19%) | J9: Neto liquidado | L9: SAC proporcional
C10: =COUNT(Reporte!$K$2:$K$1000) | D10: =IFERROR(INDEX(LIQUIDACION!$S:$S,IFERROR(MATCH("Total general",LIQUIDACION!$B:$B,0),MATCH("Total Result",LIQUIDACION!$B:$B,0))),0) | F10: =-IFERROR(INDEX(LIQUIDACION!$U:$U,IFERROR(MATCH("Total general",LIQUIDACION!$B:$B,0),MATCH("Total Result",LIQUIDACION!$B:$B,0))),0) | J10: =IFERROR(INDEX(LIQUIDACION!$W:$W,IFERROR(MATCH("Total general",LIQUIDACION!$B:$B,0),MATCH("Total Result",LIQUIDACION!$B:$B,0))),0) | L10: =IFERROR(INDEX(LIQUIDACION!$R:$R,IFERROR(MATCH("Total general",LIQUIDACION!$B:$B,0),MATCH("Total Result",LIQUIDACION!$B:$B,0))),0)
B12: 1. Distribución por categoría del convenio
B13: N° | C13: Categoría | D13: Valor prom. jornada | E13: Personas | F13: Jornadas | G13: Neto pactado | H13: % del total
D14: =IFERROR(SUMIFS(Reporte!$J$2:$J$1000,Reporte!$G$2:$G$1000,$C14)/SUMIFS(Reporte!$H$2:$H$1000,Reporte!$G$2:$G$1000,$C14),0) | E14: =SUMPRODUCT((Reporte!$G$2:$G$1000=$C14)/COUNTIFS(Reporte!$E$2:$E$1000,Reporte!$E$2:$E$1000&"",Reporte!$G$2:$G$1000,Reporte!$G$2:$G$1000&"")) | F14: =SUMIFS(Reporte!$H$2:$H$1000,Reporte!$G$2:$G$1000,$C14) | G14: =SUMIFS(Reporte!$J$2:$J$1000,Reporte!$G$2:$G$1000,$C14) | H14: =IFERROR(G14/$G$23,0)
D15: =IFERROR(SUMIFS(Reporte!$J$2:$J$1000,Reporte!$G$2:$G$1000,$C15)/SUMIFS(Reporte!$H$2:$H$1000,Reporte!$G$2:$G$1000,$C15),0) | E15: =SUMPRODUCT((Reporte!$G$2:$G$1000=$C15)/COUNTIFS(Reporte!$E$2:$E$1000,Reporte!$E$2:$E$1000&"",Reporte!$G$2:$G$1000,Reporte!$G$2:$G$1000&"")) | F15: =SUMIFS(Reporte!$H$2:$H$1000,Reporte!$G$2:$G$1000,$C15) | G15: =SUMIFS(Reporte!$J$2:$J$1000,Reporte!$G$2:$G$1000,$C15) | H15: =IFERROR(G15/$G$23,0)
D16: =IFERROR(SUMIFS(Reporte!$J$2:$J$1000,Reporte!$G$2:$G$1000,$C16)/SUMIFS(Reporte!$H$2:$H$1000,Reporte!$G$2:$G$1000,$C16),0) | E16: =SUMPRODUCT((Reporte!$G$2:$G$1000=$C16)/COUNTIFS(Reporte!$E$2:$E$1000,Reporte!$E$2:$E$1000&"",Reporte!$G$2:$G$1000,Reporte!$G$2:$G$1000&"")) | F16: =SUMIFS(Reporte!$H$2:$H$1000,Reporte!$G$2:$G$1000,$C16) | G16: =SUMIFS(Reporte!$J$2:$J$1000,Reporte!$G$2:$G$1000,$C16) | H16: =IFERROR(G16/$G$23,0)
D17: =IFERROR(SUMIFS(Reporte!$J$2:$J$1000,Reporte!$G$2:$G$1000,$C17)/SUMIFS(Reporte!$H$2:$H$1000,Reporte!$G$2:$G$1000,$C17),0) | E17: =SUMPRODUCT((Reporte!$G$2:$G$1000=$C17)/COUNTIFS(Reporte!$E$2:$E$1000,Reporte!$E$2:$E$1000&"",Reporte!$G$2:$G$1000,Reporte!$G$2:$G$1000&"")) | F17: =SUMIFS(Reporte!$H$2:$H$1000,Reporte!$G$2:$G$1000,$C17) | G17: =SUMIFS(Reporte!$J$2:$J$1000,Reporte!$G$2:$G$1000,$C17) | H17: =IFERROR(G17/$G$23,0)
D18: =IFERROR(SUMIFS(Reporte!$J$2:$J$1000,Reporte!$G$2:$G$1000,$C18)/SUMIFS(Reporte!$H$2:$H$1000,Reporte!$G$2:$G$1000,$C18),0) | E18: =SUMPRODUCT((Reporte!$G$2:$G$1000=$C18)/COUNTIFS(Reporte!$E$2:$E$1000,Reporte!$E$2:$E$1000&"",Reporte!$G$2:$G$1000,Reporte!$G$2:$G$1000&"")) | F18: =SUMIFS(Reporte!$H$2:$H$1000,Reporte!$G$2:$G$1000,$C18) | G18: =SUMIFS(Reporte!$J$2:$J$1000,Reporte!$G$2:$G$1000,$C18) | H18: =IFERROR(G18/$G$23,0)
D19: =IFERROR(SUMIFS(Reporte!$J$2:$J$1000,Reporte!$G$2:$G$1000,$C19)/SUMIFS(Reporte!$H$2:$H$1000,Reporte!$G$2:$G$1000,$C19),0) | E19: =SUMPRODUCT((Reporte!$G$2:$G$1000=$C19)/COUNTIFS(Reporte!$E$2:$E$1000,Reporte!$E$2:$E$1000&"",Reporte!$G$2:$G$1000,Reporte!$G$2:$G$1000&"")) | F19: =SUMIFS(Reporte!$H$2:$H$1000,Reporte!$G$2:$G$1000,$C19) | G19: =SUMIFS(Reporte!$J$2:$J$1000,Reporte!$G$2:$G$1000,$C19) | H19: =IFERROR(G19/$G$23,0)
D20: =IFERROR(SUMIFS(Reporte!$J$2:$J$1000,Reporte!$G$2:$G$1000,$C20)/SUMIFS(Reporte!$H$2:$H$1000,Reporte!$G$2:$G$1000,$C20),0) | E20: =SUMPRODUCT((Reporte!$G$2:$G$1000=$C20)/COUNTIFS(Reporte!$E$2:$E$1000,Reporte!$E$2:$E$1000&"",Reporte!$G$2:$G$1000,Reporte!$G$2:$G$1000&"")) | F20: =SUMIFS(Reporte!$H$2:$H$1000,Reporte!$G$2:$G$1000,$C20) | G20: =SUMIFS(Reporte!$J$2:$J$1000,Reporte!$G$2:$G$1000,$C20) | H20: =IFERROR(G20/$G$23,0)
D21: =IFERROR(SUMIFS(Reporte!$J$2:$J$1000,Reporte!$G$2:$G$1000,$C21)/SUMIFS(Reporte!$H$2:$H$1000,Reporte!$G$2:$G$1000,$C21),0) | E21: =SUMPRODUCT((Reporte!$G$2:$G$1000=$C21)/COUNTIFS(Reporte!$E$2:$E$1000,Reporte!$E$2:$E$1000&"",Reporte!$G$2:$G$1000,Reporte!$G$2:$G$1000&"")) | F21: =SUMIFS(Reporte!$H$2:$H$1000,Reporte!$G$2:$G$1000,$C21) | G21: =SUMIFS(Reporte!$J$2:$J$1000,Reporte!$G$2:$G$1000,$C21) | H21: =IFERROR(G21/$G$23,0)
D22: =IFERROR(SUMIFS(Reporte!$J$2:$J$1000,Reporte!$G$2:$G$1000,$C22)/SUMIFS(Reporte!$H$2:$H$1000,Reporte!$G$2:$G$1000,$C22),0) | E22: =SUMPRODUCT((Reporte!$G$2:$G$1000=$C22)/COUNTIFS(Reporte!$E$2:$E$1000,Reporte!$E$2:$E$1000&"",Reporte!$G$2:$G$1000,Reporte!$G$2:$G$1000&"")) | F22: =SUMIFS(Reporte!$H$2:$H$1000,Reporte!$G$2:$G$1000,$C22) | G22: =SUMIFS(Reporte!$J$2:$J$1000,Reporte!$G$2:$G$1000,$C22) | H22: =IFERROR(G22/$G$23,0)
C23: TOTAL | E23: =SUM(E14:E22) | F23: =SUM(F14:F22) | G23: =SUM(G14:G22) | H23: =SUM(H14:H22)
C24: =IF(F23<>D7,"⚠ Hay jornadas con categoría no listada en esta tabla","✓ Cuadra con el total de jornadas") | F24: Personas: una misma persona puede trabajar en más de una categoría.
B26: 2. Jornadas según día de la semana
C27: Día | D27: Jornadas | E27: % jornadas | F27: Contratos
C28: Lunes | D28: =SUMPRODUCT((Reporte!$K$2:$K$1000<>"")*(WEEKDAY(Reporte!$K$2:$K$1000,2)=1)*Reporte!$H$2:$H$1000) | E28: =IFERROR(D28/$D$7,0) | F28: =SUMPRODUCT((Reporte!$K$2:$K$1000<>"")*(WEEKDAY(Reporte!$K$2:$K$1000,2)=1))
C29: Martes | D29: =SUMPRODUCT((Reporte!$K$2:$K$1000<>"")*(WEEKDAY(Reporte!$K$2:$K$1000,2)=2)*Reporte!$H$2:$H$1000) | E29: =IFERROR(D29/$D$7,0) | F29: =SUMPRODUCT((Reporte!$K$2:$K$1000<>"")*(WEEKDAY(Reporte!$K$2:$K$1000,2)=2))
C30: Miércoles | D30: =SUMPRODUCT((Reporte!$K$2:$K$1000<>"")*(WEEKDAY(Reporte!$K$2:$K$1000,2)=3)*Reporte!$H$2:$H$1000) | E30: =IFERROR(D30/$D$7,0) | F30: =SUMPRODUCT((Reporte!$K$2:$K$1000<>"")*(WEEKDAY(Reporte!$K$2:$K$1000,2)=3))
C31: Jueves | D31: =SUMPRODUCT((Reporte!$K$2:$K$1000<>"")*(WEEKDAY(Reporte!$K$2:$K$1000,2)=4)*Reporte!$H$2:$H$1000) | E31: =IFERROR(D31/$D$7,0) | F31: =SUMPRODUCT((Reporte!$K$2:$K$1000<>"")*(WEEKDAY(Reporte!$K$2:$K$1000,2)=4))
C32: Viernes | D32: =SUMPRODUCT((Reporte!$K$2:$K$1000<>"")*(WEEKDAY(Reporte!$K$2:$K$1000,2)=5)*Reporte!$H$2:$H$1000) | E32: =IFERROR(D32/$D$7,0) | F32: =SUMPRODUCT((Reporte!$K$2:$K$1000<>"")*(WEEKDAY(Reporte!$K$2:$K$1000,2)=5))
C33: Sábado | D33: =SUMPRODUCT((Reporte!$K$2:$K$1000<>"")*(WEEKDAY(Reporte!$K$2:$K$1000,2)=6)*Reporte!$H$2:$H$1000) | E33: =IFERROR(D33/$D$7,0) | F33: =SUMPRODUCT((Reporte!$K$2:$K$1000<>"")*(WEEKDAY(Reporte!$K$2:$K$1000,2)=6))
C34: Domingo | D34: =SUMPRODUCT((Reporte!$K$2:$K$1000<>"")*(WEEKDAY(Reporte!$K$2:$K$1000,2)=7)*Reporte!$H$2:$H$1000) | E34: =IFERROR(D34/$D$7,0) | F34: =SUMPRODUCT((Reporte!$K$2:$K$1000<>"")*(WEEKDAY(Reporte!$K$2:$K$1000,2)=7))
C35: Fin de semana (sáb + dom) | D35: =D33+D34 | E35: =E33+E34 | F35: =F33+F34
C36: Nota: se asigna cada contrato al día de su fecha de alta.
B38: 3. Evolución diaria de jornadas en el mes | Q38: Datos gráfico diario
Q39: Día | R39: Jornadas | S39: Neto pactado
Q40: 1 | R40: =SUMPRODUCT((Reporte!$K$2:$K$1000<>"")*(YEAR(Reporte!$K$2:$K$1000)=YEAR($D$4))*(MONTH(Reporte!$K$2:$K$1000)=MONTH($D$4))*(DAY(Reporte!$K$2:$K$1000)=1)*Reporte!$H$2:$H$1000) | S40: =SUMPRODUCT((Reporte!$K$2:$K$1000<>"")*(YEAR(Reporte!$K$2:$K$1000)=YEAR($D$4))*(MONTH(Reporte!$K$2:$K$1000)=MONTH($D$4))*(DAY(Reporte!$K$2:$K$1000)=1)*Reporte!$J$2:$J$1000)
Q41: 2 | R41: =SUMPRODUCT((Reporte!$K$2:$K$1000<>"")*(YEAR(Reporte!$K$2:$K$1000)=YEAR($D$4))*(MONTH(Reporte!$K$2:$K$1000)=MONTH($D$4))*(DAY(Reporte!$K$2:$K$1000)=2)*Reporte!$H$2:$H$1000) | S41: =SUMPRODUCT((Reporte!$K$2:$K$1000<>"")*(YEAR(Reporte!$K$2:$K$1000)=YEAR($D$4))*(MONTH(Reporte!$K$2:$K$1000)=MONTH($D$4))*(DAY(Reporte!$K$2:$K$1000)=2)*Reporte!$J$2:$J$1000)
Q42: 3 | R42: =SUMPRODUCT((Reporte!$K$2:$K$1000<>"")*(YEAR(Reporte!$K$2:$K$1000)=YEAR($D$4))*(MONTH(Reporte!$K$2:$K$1000)=MONTH($D$4))*(DAY(Reporte!$K$2:$K$1000)=3)*Reporte!$H$2:$H$1000) | S42: =SUMPRODUCT((Reporte!$K$2:$K$1000<>"")*(YEAR(Reporte!$K$2:$K$1000)=YEAR($D$4))*(MONTH(Reporte!$K$2:$K$1000)=MONTH($D$4))*(DAY(Reporte!$K$2:$K$1000)=3)*Reporte!$J$2:$J$1000)
Q43: 4 | R43: =SUMPRODUCT((Reporte!$K$2:$K$1000<>"")*(YEAR(Reporte!$K$2:$K$1000)=YEAR($D$4))*(MONTH(Reporte!$K$2:$K$1000)=MONTH($D$4))*(DAY(Reporte!$K$2:$K$1000)=4)*Reporte!$H$2:$H$1000) | S43: =SUMPRODUCT((Reporte!$K$2:$K$1000<>"")*(YEAR(Reporte!$K$2:$K$1000)=YEAR($D$4))*(MONTH(Reporte!$K$2:$K$1000)=MONTH($D$4))*(DAY(Reporte!$K$2:$K$1000)=4)*Reporte!$J$2:$J$1000)
Q44: 5 | R44: =SUMPRODUCT((Reporte!$K$2:$K$1000<>"")*(YEAR(Reporte!$K$2:$K$1000)=YEAR($D$4))*(MONTH(Reporte!$K$2:$K$1000)=MONTH($D$4))*(DAY(Reporte!$K$2:$K$1000)=5)*Reporte!$H$2:$H$1000) | S44: =SUMPRODUCT((Reporte!$K$2:$K$1000<>"")*(YEAR(Reporte!$K$2:$K$1000)=YEAR($D$4))*(MONTH(Reporte!$K$2:$K$1000)=MONTH($D$4))*(DAY(Reporte!$K$2:$K$1000)=5)*Reporte!$J$2:$J$1000)
Q45: 6 | R45: =SUMPRODUCT((Reporte!$K$2:$K$1000<>"")*(YEAR(Reporte!$K$2:$K$1000)=YEAR($D$4))*(MONTH(Reporte!$K$2:$K$1000)=MONTH($D$4))*(DAY(Reporte!$K$2:$K$1000)=6)*Reporte!$H$2:$H$1000) | S45: =SUMPRODUCT((Reporte!$K$2:$K$1000<>"")*(YEAR(Reporte!$K$2:$K$1000)=YEAR($D$4))*(MONTH(Reporte!$K$2:$K$1000)=MONTH($D$4))*(DAY(Reporte!$K$2:$K$1000)=6)*Reporte!$J$2:$J$1000)
Q46: 7 | R46: =SUMPRODUCT((Reporte!$K$2:$K$1000<>"")*(YEAR(Reporte!$K$2:$K$1000)=YEAR($D$4))*(MONTH(Reporte!$K$2:$K$1000)=MONTH($D$4))*(DAY(Reporte!$K$2:$K$1000)=7)*Reporte!$H$2:$H$1000) | S46: =SUMPRODUCT((Reporte!$K$2:$K$1000<>"")*(YEAR(Reporte!$K$2:$K$1000)=YEAR($D$4))*(MONTH(Reporte!$K$2:$K$1000)=MONTH($D$4))*(DAY(Reporte!$K$2:$K$1000)=7)*Reporte!$J$2:$J$1000)
...

Sheet Reporte
A1: numero_legajo_tango | B1: apellido | C1: nombre_empleado | D1: apellido & nombre | E1: apellido & nombre | F1: numero_categoria | G1: nombre_categoria | H1: cantidad_jornadas_laborales | I1: sueldo_jornada | J1: sueldo_mano | K1: fecha_alta_contrato | L1: fecha_baja_contrato | M1: CONTROL TRELLO

Sheet SUBTOTAL
A1: numero_legajo_tango | B1: apellido | C1: nombre_empleado | D1: apellido & nombre | E1: apellido & nombre | F1: numero_categoria | G1: nombre_categoria | H1: cantidad_jornadas_laborales | I1: sueldo_jornada | J1: sueldo_mano | K1: fecha_alta_contrato | L1: fecha_baja_contrato
E2: Total general | H2: =SUBTOTAL(9,H2:H1) | I2: =SUBTOTAL(9,I2:I1) | J2: =SUBTOTAL(9,J2:J1)

Sheet LIQUIDACION
B1: TOTAL JORNALEROS SEPTIEMBRE | C1: =SUMPRODUCT((B5:B4<>"")/COUNTIF(B5:B4,B5:B4&""))
H2: ESCALA | O2: 11236.462 | P2: CONCEPTO 29 | Q2: CONCEPTO 30 | AI2: ESCALA POR CATEGORÍA (H:J se buscan acá)
A3: LEGAJO | C3: Valores | F3: N° Categoria | G3: Categoria | H3: Básico | I3: Adic. Sattsaid | J3: ART 8,7 | L3: Jornadas | M3: Jornal | N3: Presentismo | O3: Antigüedad | P3: Adic. Especial | Q3: Adic. Especial LN | R3: SAC Prop | S3: TOTAL BRUTO | T3: Fondo Medicamentos | U3: Aportes | V3: Adelanto | W3: Neto | X3: Neto Memo | Y3: Diferencia | Z3: Neto Pactado | AA3: Control | AC3: CONTROL SIN SAC | AI3: N° Categoria | AJ3: Básico | AK3: Adic. Sattsaid | AL3: ART 8,7
A4: =IF(OR($B4="",OR($B4="Total general",$B4="Total Result"),NOT(ISNUMBER($D4))),"",IFERROR(INDEX(Reporte!$A$2:$A$2,MATCH($B4,Reporte!$E$2:$E$2,0))&"","")) | B4: APELLIDO & NOMBRE | C4: Q PERSONAS | D4: Q JORNADAS | E4: NETO PACTADO | F4: =IF(OR($B4="",OR($B4="Total general",$B4="Total Result"),NOT(ISNUMBER($D4))),"",IFERROR(VLOOKUP($B4,Reporte!$E$2:$F$2,2,FALSE),"")) | G4: =IF(OR($B4="",OR($B4="Total general",$B4="Total Result"),NOT(ISNUMBER($D4))),"",IFERROR(VLOOKUP($B4,Reporte!$E$2:$G$2,3,FALSE),"")) | H4: =IF(OR($B4="",OR($B4="Total general",$B4="Total Result"),NOT(ISNUMBER($D4))),"",IFERROR(VLOOKUP($F4,$AI$4:$AL$4,2,FALSE),0)) | I4: =IF(OR($B4="",OR($B4="Total general",$B4="Total Result"),NOT(ISNUMBER($D4))),"",IFERROR(VLOOKUP($F4,$AI$4:$AL$4,3,FALSE),0)) | J4: =IF(OR($B4="",OR($B4="Total general",$B4="Total Result"),NOT(ISNUMBER($D4))),"",IFERROR(VLOOKUP($F4,$AI$4:$AL$4,4,FALSE),0)) | L4: =IF(OR($B4="",NOT(ISNUMBER($D4))),"",IF(OR($B4="Total general",$B4="Total Result"),SUM(L$4:L3),+D4)) | M4: =IF(OR($B4="",NOT(ISNUMBER($D4))),"",IF(OR($B4="Total general",$B4="Total Result"),SUM(M$4:M3),+L4*J4)) | N4: =IF(OR($B4="",NOT(ISNUMBER($D4))),"",IF(OR($B4="Total general",$B4="Total Result"),SUM(N$4:N3),+M4*0.1)) | R4: =IF(OR($B4="",NOT(ISNUMBER($D4))),"",IF(OR($B4="Total general",$B4="Total Result"),SUM(R$4:R3),SUM(M4:Q4)/12)) | S4: =IF(OR($B4="",NOT(ISNUMBER($D4))),"",IF(OR($B4="Total general",$B4="Total Result"),SUM(S$4:S3),SUM(M4:R4))) | U4: =IF(OR($B4="",NOT(ISNUMBER($D4))),"",IF(OR($B4="Total general",$B4="Total Result"),SUM(U$4:U3),(S4)*19%*-1)) | W4: =IF(OR($B4="",NOT(ISNUMBER($D4))),"",IF(OR($B4="Total general",$B4="Total Result"),SUM(W$4:W3),+S4+U4)) | Y4: =IF(OR($B4="",NOT(ISNUMBER($D4))),"",IF(OR($B4="Total general",$B4="Total Result"),SUM(Y$4:Y3),+W4-X4)) | Z4: =IF(OR($B4="",NOT(ISNUMBER($D4))),"",IF(OR($B4="Total general",$B4="Total Result"),SUM(Z$4:Z3),+E4)) | AA4: =IF(OR($B4="",NOT(ISNUMBER($D4))),"",IF(OR($B4="Total general",$B4="Total Result"),SUM(AA$4:AA3),+Z4-W4)) | AC4: =IF(OR($B4="",NOT(ISNUMBER($D4))),"",IF(OR($B4="Total general",$B4="Total Result"),SUM(AC$4:AC3),(+M4+N4))) | AD4: =IF(OR($B4="",NOT(ISNUMBER($D4))),"",IF(OR($B4="Total general",$B4="Total Result"),SUM(AD$4:AD3),+AC4*19%)) | AE4: =IF(OR($B4="",NOT(ISNUMBER($D4))),"",IF(OR($B4="Total general",$B4="Total Result"),SUM(AE$4:AE3),+AC4-AD4)) | AF4: =IF(OR($B4="",NOT(ISNUMBER($D4))),"",IF(OR($B4="Total general",$B4="Total Result"),SUM(AF$4:AF3),+AE4-Z4))
A5: =IF(OR($B5="",OR($B5="Total general",$B5="Total Result"),NOT(ISNUMBER($D5))),"",IFERROR(INDEX(Reporte!$A$2:$A$2,MATCH($B5,Reporte!$E$2:$E$2,0))&"","")) | B5: Total general | C5: 0 | D5: 0 | E5: 0 | F5: =IF(OR($B5="",OR($B5="Total general",$B5="Total Result"),NOT(ISNUMBER($D5))),"",IFERROR(VLOOKUP($B5,Reporte!$E$2:$F$2,2,FALSE),"")) | G5: =IF(OR($B5="",OR($B5="Total general",$B5="Total Result"),NOT(ISNUMBER($D5))),"",IFERROR(VLOOKUP($B5,Reporte!$E$2:$G$2,3,FALSE),"")) | H5: =IF(OR($B5="",OR($B5="Total general",$B5="Total Result"),NOT(ISNUMBER($D5))),"",IFERROR(VLOOKUP($F5,$AI$4:$AL$4,2,FALSE),0)) | I5: =IF(OR($B5="",OR($B5="Total general",$B5="Total Result"),NOT(ISNUMBER($D5))),"",IFERROR(VLOOKUP($F5,$AI$4:$AL$4,3,FALSE),0)) | J5: =IF(OR($B5="",OR($B5="Total general",$B5="Total Result"),NOT(ISNUMBER($D5))),"",IFERROR(VLOOKUP($F5,$AI$4:$AL$4,4,FALSE),0)) | L5: =IF(OR($B5="",NOT(ISNUMBER($D5))),"",IF(OR($B5="Total general",$B5="Total Result"),SUM(L$4:L4),+D5)) | M5: =IF(OR($B5="",NOT(ISNUMBER($D5))),"",IF(OR($B5="Total general",$B5="Total Result"),SUM(M$4:M4),+L5*J5)) | N5: =IF(OR($B5="",NOT(ISNUMBER($D5))),"",IF(OR($B5="Total general",$B5="Total Result"),SUM(N$4:N4),+M5*0.1)) | R5: =IF(OR($B5="",NOT(ISNUMBER($D5))),"",IF(OR($B5="Total general",$B5="Total Result"),SUM(R$4:R4),SUM(M5:Q5)/12)) | S5: =IF(OR($B5="",NOT(ISNUMBER($D5))),"",IF(OR($B5="Total general",$B5="Total Result"),SUM(S$4:S4),SUM(M5:R5))) | U5: =IF(OR($B5="",NOT(ISNUMBER($D5))),"",IF(OR($B5="Total general",$B5="Total Result"),SUM(U$4:U4),(S5)*19%*-1)) | W5: =IF(OR($B5="",NOT(ISNUMBER($D5))),"",IF(OR($B5="Total general",$B5="Total Result"),SUM(W$4:W4),+S5+U5)) | Y5: =IF(OR($B5="",NOT(ISNUMBER($D5))),"",IF(OR($B5="Total general",$B5="Total Result"),SUM(Y$4:Y4),+W5-X5)) | Z5: =IF(OR($B5="",NOT(ISNUMBER($D5))),"",IF(OR($B5="Total general",$B5="Total Result"),SUM(Z$4:Z4),+E5)) | AA5: =IF(OR($B5="",NOT(ISNUMBER($D5))),"",IF(OR($B5="Total general",$B5="Total Result"),SUM(AA$4:AA4),+Z5-W5)) | AC5: =IF(OR($B5="",NOT(ISNUMBER($D5))),"",IF(OR($B5="Total general",$B5="Total Result"),SUM(AC$4:AC4),(+M5+N5))) | AD5: =IF(OR($B5="",NOT(ISNUMBER($D5))),"",IF(OR($B5="Total general",$B5="Total Result"),SUM(AD$4:AD4),+AC5*19%)) | AE5: =IF(OR($B5="",NOT(ISNUMBER($D5))),"",IF(OR($B5="Total general",$B5="Total Result"),SUM(AE$4:AE4),+AC5-AD5)) | AF5: =IF(OR($B5="",NOT(ISNUMBER($D5))),"",IF(OR($B5="Total general",$B5="Total Result"),SUM(AF$4:AF4),+AE5-Z5))
A6: =IF(OR($B6="",OR($B6="Total general",$B6="Total Result"),NOT(ISNUMBER($D6))),"",IFERROR(INDEX(Reporte!$A$2:$A$2,MATCH($B6,Reporte!$E$2:$E$2,0))&"","")) | F6: =IF(OR($B6="",OR($B6="Total general",$B6="Total Result"),NOT(ISNUMBER($D6))),"",IFERROR(VLOOKUP($B6,Reporte!$E$2:$F$2,2,FALSE),"")) | G6: =IF(OR($B6="",OR($B6="Total general",$B6="Total Result"),NOT(ISNUMBER($D6))),"",IFERROR(VLOOKUP($B6,Reporte!$E$2:$G$2,3,FALSE),"")) | H6: =IF(OR($B6="",OR($B6="Total general",$B6="Total Result"),NOT(ISNUMBER($D6))),"",IFERROR(VLOOKUP($F6,$AI$4:$AL$4,2,FALSE),0)) | I6: =IF(OR($B6="",OR($B6="Total general",$B6="Total Result"),NOT(ISNUMBER($D6))),"",IFERROR(VLOOKUP($F6,$AI$4:$AL$4,3,FALSE),0)) | J6: =IF(OR($B6="",OR($B6="Total general",$B6="Total Result"),NOT(ISNUMBER($D6))),"",IFERROR(VLOOKUP($F6,$AI$4:$AL$4,4,FALSE),0)) | L6: =IF(OR($B6="",NOT(ISNUMBER($D6))),"",IF(OR($B6="Total general",$B6="Total Result"),SUM(L$4:L5),+D6)) | M6: =IF(OR($B6="",NOT(ISNUMBER($D6))),"",IF(OR($B6="Total general",$B6="Total Result"),SUM(M$4:M5),+L6*J6)) | N6: =IF(OR($B6="",NOT(ISNUMBER($D6))),"",IF(OR($B6="Total general",$B6="Total Result"),SUM(N$4:N5),+M6*0.1)) | R6: =IF(OR($B6="",NOT(ISNUMBER($D6))),"",IF(OR($B6="Total general",$B6="Total Result"),SUM(R$4:R5),SUM(M6:Q6)/12)) | S6: =IF(OR($B6="",NOT(ISNUMBER($D6))),"",IF(OR($B6="Total general",$B6="Total Result"),SUM(S$4:S5),SUM(M6:R6))) | U6: =IF(OR($B6="",NOT(ISNUMBER($D6))),"",IF(OR($B6="Total general",$B6="Total Result"),SUM(U$4:U5),(S6)*19%*-1)) | W6: =IF(OR($B6="",NOT(ISNUMBER($D6))),"",IF(OR($B6="Total general",$B6="Total Result"),SUM(W$4:W5),+S6+U6)) | Y6: =IF(OR($B6="",NOT(ISNUMBER($D6))),"",IF(OR($B6="Total general",$B6="Total Result"),SUM(Y$4:Y5),+W6-X6)) | Z6: =IF(OR($B6="",NOT(ISNUMBER($D6))),"",IF(OR($B6="Total general",$B6="Total Result"),SUM(Z$4:Z5),+E6)) | AA6: =IF(OR($B6="",NOT(ISNUMBER($D6))),"",IF(OR($B6="Total general",$B6="Total Result"),SUM(AA$4:AA5),+Z6-W6)) | AC6: =IF(OR($B6="",NOT(ISNUMBER($D6))),"",IF(OR($B6="Total general",$B6="Total Result"),SUM(AC$4:AC5),(+M6+N6))) | AD6: =IF(OR($B6="",NOT(ISNUMBER($D6))),"",IF(OR($B6="Total general",$B6="Total Result"),SUM(AD$4:AD5),+AC6*19%)) | AE6: =IF(OR($B6="",NOT(ISNUMBER($D6))),"",IF(OR($B6="Total general",$B6="Total Result"),SUM(AE$4:AE5),+AC6-AD6)) | AF6: =IF(OR($B6="",NOT(ISNUMBER($D6))),"",IF(OR($B6="Total general",$B6="Total Result"),SUM(AF$4:AF5),+AE6-Z6))
A7: =IF(OR($B7="",OR($B7="Total general",$B7="Total Result"),NOT(ISNUMBER($D7))),"",IFERROR(INDEX(Reporte!$A$2:$A$2,MATCH($B7,Reporte!$E$2:$E$2,0))&"","")) | F7: =IF(OR($B7="",OR($B7="Total general",$B7="Total Result"),NOT(ISNUMBER($D7))),"",IFERROR(VLOOKUP($B7,Reporte!$E$2:$F$2,2,FALSE),"")) | G7: =IF(OR($B7="",OR($B7="Total general",$B7="Total Result"),NOT(ISNUMBER($D7))),"",IFERROR(VLOOKUP($B7,Reporte!$E$2:$G$2,3,FALSE),"")) | H7: =IF(OR($B7="",OR($B7="Total general",$B7="Total Result"),NOT(ISNUMBER($D7))),"",IFERROR(VLOOKUP($F7,$AI$4:$AL$4,2,FALSE),0)) | I7: =IF(OR($B7="",OR($B7="Total general",$B7="Total Result"),NOT(ISNUMBER($D7))),"",IFERROR(VLOOKUP($F7,$AI$4:$AL$4,3,FALSE),0)) | J7: =IF(OR($B7="",OR($B7="Total general",$B7="Total Result"),NOT(ISNUMBER($D7))),"",IFERROR(VLOOKUP($F7,$AI$4:$AL$4,4,FALSE),0)) | L7: =IF(OR($B7="",NOT(ISNUMBER($D7))),"",IF(OR($B7="Total general",$B7="Total Result"),SUM(L$4:L6),+D7)) | M7: =IF(OR($B7="",NOT(ISNUMBER($D7))),"",IF(OR($B7="Total general",$B7="Total Result"),SUM(M$4:M6),+L7*J7)) | N7: =IF(OR($B7="",NOT(ISNUMBER($D7))),"",IF(OR($B7="Total general",$B7="Total Result"),SUM(N$4:N6),+M7*0.1)) | R7: =IF(OR($B7="",NOT(ISNUMBER($D7))),"",IF(OR($B7="Total general",$B7="Total Result"),SUM(R$4:R6),SUM(M7:Q7)/12)) | S7: =IF(OR($B7="",NOT(ISNUMBER($D7))),"",IF(OR($B7="Total general",$B7="Total Result"),SUM(S$4:S6),SUM(M7:R7))) | U7: =IF(OR($B7="",NOT(ISNUMBER($D7))),"",IF(OR($B7="Total general",$B7="Total Result"),SUM(U$4:U6),(S7)*19%*-1)) | W7: =IF(OR($B7="",NOT(ISNUMBER($D7))),"",IF(OR($B7="Total general",$B7="Total Result"),SUM(W$4:W6),+S7+U7)) | Y7: =IF(OR($B7="",NOT(ISNUMBER($D7))),"",IF(OR($B7="Total general",$B7="Total Result"),SUM(Y$4:Y6),+W7-X7)) | Z7: =IF(OR($B7="",NOT(ISNUMBER($D7))),"",IF(OR($B7="Total general",$B7="Total Result"),SUM(Z$4:Z6),+E7)) | AA7: =IF(OR($B7="",NOT(ISNUMBER($D7))),"",IF(OR($B7="Total general",$B7="Total Result"),SUM(AA$4:AA6),+Z7-W7)) | AC7: =IF(OR($B7="",NOT(ISNUMBER($D7))),"",IF(OR($B7="Total general",$B7="Total Result"),SUM(AC$4:AC6),(+M7+N7))) | AD7: =IF(OR($B7="",NOT(ISNUMBER($D7))),"",IF(OR($B7="Total general",$B7="Total Result"),SUM(AD$4:AD6),+AC7*19%)) | AE7: =IF(OR($B7="",NOT(ISNUMBER($D7))),"",IF(OR($B7="Total general",$B7="Total Result"),SUM(AE$4:AE6),+AC7-AD7)) | AF7: =IF(OR($B7="",NOT(ISNUMBER($D7))),"",IF(OR($B7="Total general",$B7="Total Result"),SUM(AF$4:AF6),+AE7-Z7))
A8: =IF(OR($B8="",OR($B8="Total general",$B8="Total Result"),NOT(ISNUMBER($D8))),"",IFERROR(INDEX(Reporte!$A$2:$A$2,MATCH($B8,Reporte!$E$2:$E$2,0))&"","")) | F8: =IF(OR($B8="",OR($B8="Total general",$B8="Total Result"),NOT(ISNUMBER($D8))),"",IFERROR(VLOOKUP($B8,Reporte!$E$2:$F$2,2,FALSE),"")) | G8: =IF(OR($B8="",OR($B8="Total general",$B8="Total Result"),NOT(ISNUMBER($D8))),"",IFERROR(VLOOKUP($B8,Reporte!$E$2:$G$2,3,FALSE),"")) | H8: =IF(OR($B8="",OR($B8="Total general",$B8="Total Result"),NOT(ISNUMBER($D8))),"",IFERROR(VLOOKUP($F8,$AI$4:$AL$4,2,FALSE),0)) | I8: =IF(OR($B8="",OR($B8="Total general",$B8="Total Result"),NOT(ISNUMBER($D8))),"",IFERROR(VLOOKUP($F8,$AI$4:$AL$4,3,FALSE),0)) | J8: =IF(OR($B8="",OR($B8="Total general",$B8="Total Result"),NOT(ISNUMBER($D8))),"",IFERROR(VLOOKUP($F8,$AI$4:$AL$4,4,FALSE),0)) | L8: =IF(OR($B8="",NOT(ISNUMBER($D8))),"",IF(OR($B8="Total general",$B8="Total Result"),SUM(L$4:L7),+D8)) | M8: =IF(OR($B8="",NOT(ISNUMBER($D8))),"",IF(OR($B8="Total general",$B8="Total Result"),SUM(M$4:M7),+L8*J8)) | N8: =IF(OR($B8="",NOT(ISNUMBER($D8))),"",IF(OR($B8="Total general",$B8="Total Result"),SUM(N$4:N7),+M8*0.1)) | R8: =IF(OR($B8="",NOT(ISNUMBER($D8))),"",IF(OR($B8="Total general",$B8="Total Result"),SUM(R$4:R7),SUM(M8:Q8)/12)) | S8: =IF(OR($B8="",NOT(ISNUMBER($D8))),"",IF(OR($B8="Total general",$B8="Total Result"),SUM(S$4:S7),SUM(M8:R8))) | U8: =IF(OR($B8="",NOT(ISNUMBER($D8))),"",IF(OR($B8="Total general",$B8="Total Result"),SUM(U$4:U7),(S8)*19%*-1)) | W8: =IF(OR($B8="",NOT(ISNUMBER($D8))),"",IF(OR($B8="Total general",$B8="Total Result"),SUM(W$4:W7),+S8+U8)) | Y8: =IF(OR($B8="",NOT(ISNUMBER($D8))),"",IF(OR($B8="Total general",$B8="Total Result"),SUM(Y$4:Y7),+W8-X8)) | Z8: =IF(OR($B8="",NOT(ISNUMBER($D8))),"",IF(OR($B8="Total general",$B8="Total Result"),SUM(Z$4:Z7),+E8)) | AA8: =IF(OR($B8="",NOT(ISNUMBER($D8))),"",IF(OR($B8="Total general",$B8="Total Result"),SUM(AA$4:AA7),+Z8-W8)) | AC8: =IF(OR($B8="",NOT(ISNUMBER($D8))),"",IF(OR($B8="Total general",$B8="Total Result"),SUM(AC$4:AC7),(+M8+N8))) | AD8: =IF(OR($B8="",NOT(ISNUMBER($D8))),"",IF(OR($B8="Total general",$B8="Total Result"),SUM(AD$4:AD7),+AC8*19%)) | AE8: =IF(OR($B8="",NOT(ISNUMBER($D8))),"",IF(OR($B8="Total general",$B8="Total Result"),SUM(AE$4:AE7),+AC8-AD8)) | AF8: =IF(OR($B8="",NOT(ISNUMBER($D8))),"",IF(OR($B8="Total general",$B8="Total Result"),SUM(AF$4:AF7),+AE8-Z8))
A9: =IF(OR($B9="",OR($B9="Total general",$B9="Total Result"),NOT(ISNUMBER($D9))),"",IFERROR(INDEX(Reporte!$A$2:$A$2,MATCH($B9,Reporte!$E$2:$E$2,0))&"","")) | F9: =IF(OR($B9="",OR($B9="Total general",$B9="Total Result"),NOT(ISNUMBER($D9))),"",IFERROR(VLOOKUP($B9,Reporte!$E$2:$F$2,2,FALSE),"")) | G9: =IF(OR($B9="",OR($B9="Total general",$B9="Total Result"),NOT(ISNUMBER($D9))),"",IFERROR(VLOOKUP($B9,Reporte!$E$2:$G$2,3,FALSE),"")) | H9: =IF(OR($B9="",OR($B9="Total general",$B9="Total Result"),NOT(ISNUMBER($D9))),"",IFERROR(VLOOKUP($F9,$AI$4:$AL$4,2,FALSE),0)) | I9: =IF(OR($B9="",OR($B9="Total general",$B9="Total Result"),NOT(ISNUMBER($D9))),"",IFERROR(VLOOKUP($F9,$AI$4:$AL$4,3,FALSE),0)) | J9: =IF(OR($B9="",OR($B9="Total general",$B9="Total Result"),NOT(ISNUMBER($D9))),"",IFERROR(VLOOKUP($F9,$AI$4:$AL$4,4,FALSE),0)) | L9: =IF(OR($B9="",NOT(ISNUMBER($D9))),"",IF(OR($B9="Total general",$B9="Total Result"),SUM(L$4:L8),+D9)) | M9: =IF(OR($B9="",NOT(ISNUMBER($D9))),"",IF(OR($B9="Total general",$B9="Total Result"),SUM(M$4:M8),+L9*J9)) | N9: =IF(OR($B9="",NOT(ISNUMBER($D9))),"",IF(OR($B9="Total general",$B9="Total Result"),SUM(N$4:N8),+M9*0.1)) | R9: =IF(OR($B9="",NOT(ISNUMBER($D9))),"",IF(OR($B9="Total general",$B9="Total Result"),SUM(R$4:R8),SUM(M9:Q9)/12)) | S9: =IF(OR($B9="",NOT(ISNUMBER($D9))),"",IF(OR($B9="Total general",$B9="Total Result"),SUM(S$4:S8),SUM(M9:R9))) | U9: =IF(OR($B9="",NOT(ISNUMBER($D9))),"",IF(OR($B9="Total general",$B9="Total Result"),SUM(U$4:U8),(S9)*19%*-1)) | W9: =IF(OR($B9="",NOT(ISNUMBER($D9))),"",IF(OR($B9="Total general",$B9="Total Result"),SUM(W$4:W8),+S9+U9)) | Y9: =IF(OR($B9="",NOT(ISNUMBER($D9))),"",IF(OR($B9="Total general",$B9="Total Result"),SUM(Y$4:Y8),+W9-X9)) | Z9: =IF(OR($B9="",NOT(ISNUMBER($D9))),"",IF(OR($B9="Total general",$B9="Total Result"),SUM(Z$4:Z8),+E9)) | AA9: =IF(OR($B9="",NOT(ISNUMBER($D9))),"",IF(OR($B9="Total general",$B9="Total Result"),SUM(AA$4:AA8),+Z9-W9)) | AC9: =IF(OR($B9="",NOT(ISNUMBER($D9))),"",IF(OR($B9="Total general",$B9="Total Result"),SUM(AC$4:AC8),(+M9+N9))) | AD9: =IF(OR($B9="",NOT(ISNUMBER($D9))),"",IF(OR($B9="Total general",$B9="Total Result"),SUM(AD$4:AD8),+AC9*19%)) | AE9: =IF(OR($B9="",NOT(ISNUMBER($D9))),"",IF(OR($B9="Total general",$B9="Total Result"),SUM(AE$4:AE8),+AC9-AD9)) | AF9: =IF(OR($B9="",NOT(ISNUMBER($D9))),"",IF(OR($B9="Total general",$B9="Total Result"),SUM(AF$4:AF8),+AE9-Z9))
A10: =IF(OR($B10="",OR($B10="Total general",$B10="Total Result"),NOT(ISNUMBER($D10))),"",IFERROR(INDEX(Reporte!$A$2:$A$2,MATCH($B10,Reporte!$E$2:$E$2,0))&"","")) | F10: =IF(OR($B10="",OR($B10="Total general",$B10="Total Result"),NOT(ISNUMBER($D10))),"",IFERROR(VLOOKUP($B10,Reporte!$E$2:$F$2,2,FALSE),"")) | G10: =IF(OR($B10="",OR($B10="Total general",$B10="Total Result"),NOT(ISNUMBER($D10))),"",IFERROR(VLOOKUP($B10,Reporte!$E$2:$G$2,3,FALSE),"")) | H10: =IF(OR($B10="",OR($B10="Total general",$B10="Total Result"),NOT(ISNUMBER($D10))),"",IFERROR(VLOOKUP($F10,$AI$4:$AL$4,2,FALSE),0)) | I10: =IF(OR($B10="",OR($B10="Total general",$B10="Total Result"),NOT(ISNUMBER($D10))),"",IFERROR(VLOOKUP($F10,$AI$4:$AL$4,3,FALSE),0)) | J10: =IF(OR($B10="",OR($B10="Total general",$B10="Total Result"),NOT(ISNUMBER($D10))),"",IFERROR(VLOOKUP($F10,$AI$4:$AL$4,4,FALSE),0)) | L10: =IF(OR($B10="",NOT(ISNUMBER($D10))),"",IF(OR($B10="Total general",$B10="Total Result"),SUM(L$4:L9),+D10)) | M10: =IF(OR($B10="",NOT(ISNUMBER($D10))),"",IF(OR($B10="Total general",$B10="Total Result"),SUM(M$4:M9),+L10*J10)) | N10: =IF(OR($B10="",NOT(ISNUMBER($D10))),"",IF(OR($B10="Total general",$B10="Total Result"),SUM(N$4:N9),+M10*0.1)) | R10: =IF(OR($B10="",NOT(ISNUMBER($D10))),"",IF(OR($B10="Total general",$B10="Total Result"),SUM(R$4:R9),SUM(M10:Q10)/12)) | S10: =IF(OR($B10="",NOT(ISNUMBER($D10))),"",IF(OR($B10="Total general",$B10="Total Result"),SUM(S$4:S9),SUM(M10:R10))) | U10: =IF(OR($B10="",NOT(ISNUMBER($D10))),"",IF(OR($B10="Total general",$B10="Total Result"),SUM(U$4:U9),(S10)*19%*-1)) | W10: =IF(OR($B10="",NOT(ISNUMBER($D10))),"",IF(OR($B10="Total general",$B10="Total Result"),SUM(W$4:W9),+S10+U10)) | Y10: =IF(OR($B10="",NOT(ISNUMBER($D10))),"",IF(OR($B10="Total general",$B10="Total Result"),SUM(Y$4:Y9),+W10-X10)) | Z10: =IF(OR($B10="",NOT(ISNUMBER($D10))),"",IF(OR($B10="Total general",$B10="Total Result"),SUM(Z$4:Z9),+E10)) | AA10: =IF(OR($B10="",NOT(ISNUMBER($D10))),"",IF(OR($B10="Total general",$B10="Total Result"),SUM(AA$4:AA9),+Z10-W10)) | AC10: =IF(OR($B10="",NOT(ISNUMBER($D10))),"",IF(OR($B10="Total general",$B10="Total Result"),SUM(AC$4:AC9),(+M10+N10))) | AD10: =IF(OR($B10="",NOT(ISNUMBER($D10))),"",IF(OR($B10="Total general",$B10="Total Result"),SUM(AD$4:AD9),+AC10*19%)) | AE10: =IF(OR($B10="",NOT(ISNUMBER($D10))),"",IF(OR($B10="Total general",$B10="Total Result"),SUM(AE$4:AE9),+AC10-AD10)) | AF10: =IF(OR($B10="",NOT(ISNUMBER($D10))),"",IF(OR($B10="Total general",$B10="Total Result"),SUM(AF$4:AF9),+AE10-Z10))
A11: =IF(OR($B11="",OR($B11="Total general",$B11="Total Result"),NOT(ISNUMBER($D11))),"",IFERROR(INDEX(Reporte!$A$2:$A$2,MATCH($B11,Reporte!$E$2:$E$2,0))&"","")) | F11: =IF(OR($B11="",OR($B11="Total general",$B11="Total Result"),NOT(ISNUMBER($D11))),"",IFERROR(VLOOKUP($B11,Reporte!$E$2:$F$2,2,FALSE),"")) | G11: =IF(OR($B11="",OR($B11="Total general",$B11="Total Result"),NOT(ISNUMBER($D11))),"",IFERROR(VLOOKUP($B11,Reporte!$E$2:$G$2,3,FALSE),"")) | H11: =IF(OR($B11="",OR($B11="Total general",$B11="Total Result"),NOT(ISNUMBER($D11))),"",IFERROR(VLOOKUP($F11,$AI$4:$AL$4,2,FALSE),0)) | I11: =IF(OR($B11="",OR($B11="Total general",$B11="Total Result"),NOT(ISNUMBER($D11))),"",IFERROR(VLOOKUP($F11,$AI$4:$AL$4,3,FALSE),0)) | J11: =IF(OR($B11="",OR($B11="Total general",$B11="Total Result"),NOT(ISNUMBER($D11))),"",IFERROR(VLOOKUP($F11,$AI$4:$AL$4,4,FALSE),0)) | L11: =IF(OR($B11="",NOT(ISNUMBER($D11))),"",IF(OR($B11="Total general",$B11="Total Result"),SUM(L$4:L10),+D11)) | M11: =IF(OR($B11="",NOT(ISNUMBER($D11))),"",IF(OR($B11="Total general",$B11="Total Result"),SUM(M$4:M10),+L11*J11)) | N11: =IF(OR($B11="",NOT(ISNUMBER($D11))),"",IF(OR($B11="Total general",$B11="Total Result"),SUM(N$4:N10),+M11*0.1)) | R11: =IF(OR($B11="",NOT(ISNUMBER($D11))),"",IF(OR($B11="Total general",$B11="Total Result"),SUM(R$4:R10),SUM(M11:Q11)/12)) | S11: =IF(OR($B11="",NOT(ISNUMBER($D11))),"",IF(OR($B11="Total general",$B11="Total Result"),SUM(S$4:S10),SUM(M11:R11))) | U11: =IF(OR($B11="",NOT(ISNUMBER($D11))),"",IF(OR($B11="Total general",$B11="Total Result"),SUM(U$4:U10),(S11)*19%*-1)) | W11: =IF(OR($B11="",NOT(ISNUMBER($D11))),"",IF(OR($B11="Total general",$B11="Total Result"),SUM(W$4:W10),+S11+U11)) | Y11: =IF(OR($B11="",NOT(ISNUMBER($D11))),"",IF(OR($B11="Total general",$B11="Total Result"),SUM(Y$4:Y10),+W11-X11)) | Z11: =IF(OR($B11="",NOT(ISNUMBER($D11))),"",IF(OR($B11="Total general",$B11="Total Result"),SUM(Z$4:Z10),+E11)) | AA11: =IF(OR($B11="",NOT(ISNUMBER($D11))),"",IF(OR($B11="Total general",$B11="Total Result"),SUM(AA$4:AA10),+Z11-W11)) | AC11: =IF(OR($B11="",NOT(ISNUMBER($D11))),"",IF(OR($B11="Total general",$B11="Total Result"),SUM(AC$4:AC10),(+M11+N11))) | AD11: =IF(OR($B11="",NOT(ISNUMBER($D11))),"",IF(OR($B11="Total general",$B11="Total Result"),SUM(AD$4:AD10),+AC11*19%)) | AE11: =IF(OR($B11="",NOT(ISNUMBER($D11))),"",IF(OR($B11="Total general",$B11="Total Result"),SUM(AE$4:AE10),+AC11-AD11)) | AF11: =IF(OR($B11="",NOT(ISNUMBER($D11))),"",IF(OR($B11="Total general",$B11="Total Result"),SUM(AF$4:AF10),+AE11-Z11))
A12: =IF(OR($B12="",OR($B12="Total general",$B12="Total Result"),NOT(ISNUMBER($D12))),"",IFERROR(INDEX(Reporte!$A$2:$A$2,MATCH($B12,Reporte!$E$2:$E$2,0))&"","")) | F12: =IF(OR($B12="",OR($B12="Total general",$B12="Total Result"),NOT(ISNUMBER($D12))),"",IFERROR(VLOOKUP($B12,Reporte!$E$2:$F$2,2,FALSE),"")) | G12: =IF(OR($B12="",OR($B12="Total general",$B12="Total Result"),NOT(ISNUMBER($D12))),"",IFERROR(VLOOKUP($B12,Reporte!$E$2:$G$2,3,FALSE),"")) | H12: =IF(OR($B12="",OR($B12="Total general",$B12="Total Result"),NOT(ISNUMBER($D12))),"",IFERROR(VLOOKUP($F12,$AI$4:$AL$4,2,FALSE),0)) | I12: =IF(OR($B12="",OR($B12="Total general",$B12="Total Result"),NOT(ISNUMBER($D12))),"",IFERROR(VLOOKUP($F12,$AI$4:$AL$4,3,FALSE),0)) | J12: =IF(OR($B12="",OR($B12="Total general",$B12="Total Result"),NOT(ISNUMBER($D12))),"",IFERROR(VLOOKUP($F12,$AI$4:$AL$4,4,FALSE),0)) | L12: =IF(OR($B12="",NOT(ISNUMBER($D12))),"",IF(OR($B12="Total general",$B12="Total Result"),SUM(L$4:L11),+D12)) | M12: =IF(OR($B12="",NOT(ISNUMBER($D12))),"",IF(OR($B12="Total general",$B12="Total Result"),SUM(M$4:M11),+L12*J12)) | N12: =IF(OR($B12="",NOT(ISNUMBER($D12))),"",IF(OR($B12="Total general",$B12="Total Result"),SUM(N$4:N11),+M12*0.1)) | R12: =IF(OR($B12="",NOT(ISNUMBER($D12))),"",IF(OR($B12="Total general",$B12="Total Result"),SUM(R$4:R11),SUM(M12:Q12)/12)) | S12: =IF(OR($B12="",NOT(ISNUMBER($D12))),"",IF(OR($B12="Total general",$B12="Total Result"),SUM(S$4:S11),SUM(M12:R12))) | U12: =IF(OR($B12="",NOT(ISNUMBER($D12))),"",IF(OR($B12="Total general",$B12="Total Result"),SUM(U$4:U11),(S12)*19%*-1)) | W12: =IF(OR($B12="",NOT(ISNUMBER($D12))),"",IF(OR($B12="Total general",$B12="Total Result"),SUM(W$4:W11),+S12+U12)) | Y12: =IF(OR($B12="",NOT(ISNUMBER($D12))),"",IF(OR($B12="Total general",$B12="Total Result"),SUM(Y$4:Y11),+W12-X12)) | Z12: =IF(OR($B12="",NOT(ISNUMBER($D12))),"",IF(OR($B12="Total general",$B12="Total Result"),SUM(Z$4:Z11),+E12)) | AA12: =IF(OR($B12="",NOT(ISNUMBER($D12))),"",IF(OR($B12="Total general",$B12="Total Result"),SUM(AA$4:AA11),+Z12-W12)) | AC12: =IF(OR($B12="",NOT(ISNUMBER($D12))),"",IF(OR($B12="Total general",$B12="Total Result"),SUM(AC$4:AC11),(+M12+N12))) | AD12: =IF(OR($B12="",NOT(ISNUMBER($D12))),"",IF(OR($B12="Total general",$B12="Total Result"),SUM(AD$4:AD11),+AC12*19%)) | AE12: =IF(OR($B12="",NOT(ISNUMBER($D12))),"",IF(OR($B12="Total general",$B12="Total Result"),SUM(AE$4:AE11),+AC12-AD12)) | AF12: =IF(OR($B12="",NOT(ISNUMBER($D12))),"",IF(OR($B12="Total general",$B12="Total Result"),SUM(AF$4:AF11),+AE12-Z12))
A13: =IF(OR($B13="",OR($B13="Total general",$B13="Total Result"),NOT(ISNUMBER($D13))),"",IFERROR(INDEX(Reporte!$A$2:$A$2,MATCH($B13,Reporte!$E$2:$E$2,0))&"","")) | F13: =IF(OR($B13="",OR($B13="Total general",$B13="Total Result"),NOT(ISNUMBER($D13))),"",IFERROR(VLOOKUP($B13,Reporte!$E$2:$F$2,2,FALSE),"")) | G13: =IF(OR($B13="",OR($B13="Total general",$B13="Total Result"),NOT(ISNUMBER($D13))),"",IFERROR(VLOOKUP($B13,Reporte!$E$2:$G$2,3,FALSE),"")) | H13: =IF(OR($B13="",OR($B13="Total general",$B13="Total Result"),NOT(ISNUMBER($D13))),"",IFERROR(VLOOKUP($F13,$AI$4:$AL$4,2,FALSE),0)) | I13: =IF(OR($B13="",OR($B13="Total general",$B13="Total Result"),NOT(ISNUMBER($D13))),"",IFERROR(VLOOKUP($F13,$AI$4:$AL$4,3,FALSE),0)) | J13: =IF(OR($B13="",OR($B13="Total general",$B13="Total Result"),NOT(ISNUMBER($D13))),"",IFERROR(VLOOKUP($F13,$AI$4:$AL$4,4,FALSE),0)) | L13: =IF(OR($B13="",NOT(ISNUMBER($D13))),"",IF(OR($B13="Total general",$B13="Total Result"),SUM(L$4:L12),+D13)) | M13: =IF(OR($B13="",NOT(ISNUMBER($D13))),"",IF(OR($B13="Total general",$B13="Total Result"),SUM(M$4:M12),+L13*J13)) | N13: =IF(OR($B13="",NOT(ISNUMBER($D13))),"",IF(OR($B13="Total general",$B13="Total Result"),SUM(N$4:N12),+M13*0.1)) | R13: =IF(OR($B13="",NOT(ISNUMBER($D13))),"",IF(OR($B13="Total general",$B13="Total Result"),SUM(R$4:R12),SUM(M13:Q13)/12)) | S13: =IF(OR($B13="",NOT(ISNUMBER($D13))),"",IF(OR($B13="Total general",$B13="Total Result"),SUM(S$4:S12),SUM(M13:R13))) | U13: =IF(OR($B13="",NOT(ISNUMBER($D13))),"",IF(OR($B13="Total general",$B13="Total Result"),SUM(U$4:U12),(S13)*19%*-1)) | W13: =IF(OR($B13="",NOT(ISNUMBER($D13))),"",IF(OR($B13="Total general",$B13="Total Result"),SUM(W$4:W12),+S13+U13)) | Y13: =IF(OR($B13="",NOT(ISNUMBER($D13))),"",IF(OR($B13="Total general",$B13="Total Result"),SUM(Y$4:Y12),+W13-X13)) | Z13: =IF(OR($B13="",NOT(ISNUMBER($D13))),"",IF(OR($B13="Total general",$B13="Total Result"),SUM(Z$4:Z12),+E13)) | AA13: =IF(OR($B13="",NOT(ISNUMBER($D13))),"",IF(OR($B13="Total general",$B13="Total Result"),SUM(AA$4:AA12),+Z13-W13)) | AC13: =IF(OR($B13="",NOT(ISNUMBER($D13))),"",IF(OR($B13="Total general",$B13="Total Result"),SUM(AC$4:AC12),(+M13+N13))) | AD13: =IF(OR($B13="",NOT(ISNUMBER($D13))),"",IF(OR($B13="Total general",$B13="Total Result"),SUM(AD$4:AD12),+AC13*19%)) | AE13: =IF(OR($B13="",NOT(ISNUMBER($D13))),"",IF(OR($B13="Total general",$B13="Total Result"),SUM(AE$4:AE12),+AC13-AD13)) | AF13: =IF(OR($B13="",NOT(ISNUMBER($D13))),"",IF(OR($B13="Total general",$B13="Total Result"),SUM(AF$4:AF12),+AE13-Z13))
A14: =IF(OR($B14="",OR($B14="Total general",$B14="Total Result"),NOT(ISNUMBER($D14))),"",IFERROR(INDEX(Reporte!$A$2:$A$2,MATCH($B14,Reporte!$E$2:$E$2,0))&"","")) | F14: =IF(OR($B14="",OR($B14="Total general",$B14="Total Result"),NOT(ISNUMBER($D14))),"",IFERROR(VLOOKUP($B14,Reporte!$E$2:$F$2,2,FALSE),"")) | G14: =IF(OR($B14="",OR($B14="Total general",$B14="Total Result"),NOT(ISNUMBER($D14))),"",IFERROR(VLOOKUP($B14,Reporte!$E$2:$G$2,3,FALSE),"")) | H14: =IF(OR($B14="",OR($B14="Total general",$B14="Total Result"),NOT(ISNUMBER($D14))),"",IFERROR(VLOOKUP($F14,$AI$4:$AL$4,2,FALSE),0)) | I14: =IF(OR($B14="",OR($B14="Total general",$B14="Total Result"),NOT(ISNUMBER($D14))),"",IFERROR(VLOOKUP($F14,$AI$4:$AL$4,3,FALSE),0)) | J14: =IF(OR($B14="",OR($B14="Total general",$B14="Total Result"),NOT(ISNUMBER($D14))),"",IFERROR(VLOOKUP($F14,$AI$4:$AL$4,4,FALSE),0)) | L14: =IF(OR($B14="",NOT(ISNUMBER($D14))),"",IF(OR($B14="Total general",$B14="Total Result"),SUM(L$4:L13),+D14)) | M14: =IF(OR($B14="",NOT(ISNUMBER($D14))),"",IF(OR($B14="Total general",$B14="Total Result"),SUM(M$4:M13),+L14*J14)) | N14: =IF(OR($B14="",NOT(ISNUMBER($D14))),"",IF(OR($B14="Total general",$B14="Total Result"),SUM(N$4:N13),+M14*0.1)) | R14: =IF(OR($B14="",NOT(ISNUMBER($D14))),"",IF(OR($B14="Total general",$B14="Total Result"),SUM(R$4:R13),SUM(M14:Q14)/12)) | S14: =IF(OR($B14="",NOT(ISNUMBER($D14))),"",IF(OR($B14="Total general",$B14="Total Result"),SUM(S$4:S13),SUM(M14:R14))) | U14: =IF(OR($B14="",NOT(ISNUMBER($D14))),"",IF(OR($B14="Total general",$B14="Total Result"),SUM(U$4:U13),(S14)*19%*-1)) | W14: =IF(OR($B14="",NOT(ISNUMBER($D14))),"",IF(OR($B14="Total general",$B14="Total Result"),SUM(W$4:W13),+S14+U14)) | Y14: =IF(OR($B14="",NOT(ISNUMBER($D14))),"",IF(OR($B14="Total general",$B14="Total Result"),SUM(Y$4:Y13),+W14-X14)) | Z14: =IF(OR($B14="",NOT(ISNUMBER($D14))),"",IF(OR($B14="Total general",$B14="Total Result"),SUM(Z$4:Z13),+E14)) | AA14: =IF(OR($B14="",NOT(ISNUMBER($D14))),"",IF(OR($B14="Total general",$B14="Total Result"),SUM(AA$4:AA13),+Z14-W14)) | AC14: =IF(OR($B14="",NOT(ISNUMBER($D14))),"",IF(OR($B14="Total general",$B14="Total Result"),SUM(AC$4:AC13),(+M14+N14))) | AD14: =IF(OR($B14="",NOT(ISNUMBER($D14))),"",IF(OR($B14="Total general",$B14="Total Result"),SUM(AD$4:AD13),+AC14*19%)) | AE14: =IF(OR($B14="",NOT(ISNUMBER($D14))),"",IF(OR($B14="Total general",$B14="Total Result"),SUM(AE$4:AE13),+AC14-AD14)) | AF14: =IF(OR($B14="",NOT(ISNUMBER($D14))),"",IF(OR($B14="Total general",$B14="Total Result"),SUM(AF$4:AF13),+AE14-Z14))
A15: =IF(OR($B15="",OR($B15="Total general",$B15="Total Result"),NOT(ISNUMBER($D15))),"",IFERROR(INDEX(Reporte!$A$2:$A$2,MATCH($B15,Reporte!$E$2:$E$2,0))&"","")) | F15: =IF(OR($B15="",OR($B15="Total general",$B15="Total Result"),NOT(ISNUMBER($D15))),"",IFERROR(VLOOKUP($B15,Reporte!$E$2:$F$2,2,FALSE),"")) | G15: =IF(OR($B15="",OR($B15="Total general",$B15="Total Result"),NOT(ISNUMBER($D15))),"",IFERROR(VLOOKUP($B15,Reporte!$E$2:$G$2,3,FALSE),"")) | H15: =IF(OR($B15="",OR($B15="Total general",$B15="Total Result"),NOT(ISNUMBER($D15))),"",IFERROR(VLOOKUP($F15,$AI$4:$AL$4,2,FALSE),0)) | I15: =IF(OR($B15="",OR($B15="Total general",$B15="Total Result"),NOT(ISNUMBER($D15))),"",IFERROR(VLOOKUP($F15,$AI$4:$AL$4,3,FALSE),0)) | J15: =IF(OR($B15="",OR($B15="Total general",$B15="Total Result"),NOT(ISNUMBER($D15))),"",IFERROR(VLOOKUP($F15,$AI$4:$AL$4,4,FALSE),0)) | L15: =IF(OR($B15="",NOT(ISNUMBER($D15))),"",IF(OR($B15="Total general",$B15="Total Result"),SUM(L$4:L14),+D15)) | M15: =IF(OR($B15="",NOT(ISNUMBER($D15))),"",IF(OR($B15="Total general",$B15="Total Result"),SUM(M$4:M14),+L15*J15)) | N15: =IF(OR($B15="",NOT(ISNUMBER($D15))),"",IF(OR($B15="Total general",$B15="Total Result"),SUM(N$4:N14),+M15*0.1)) | R15: =IF(OR($B15="",NOT(ISNUMBER($D15))),"",IF(OR($B15="Total general",$B15="Total Result"),SUM(R$4:R14),SUM(M15:Q15)/12)) | S15: =IF(OR($B15="",NOT(ISNUMBER($D15))),"",IF(OR($B15="Total general",$B15="Total Result"),SUM(S$4:S14),SUM(M15:R15))) | U15: =IF(OR($B15="",NOT(ISNUMBER($D15))),"",IF(OR($B15="Total general",$B15="Total Result"),SUM(U$4:U14),(S15)*19%*-1)) | W15: =IF(OR($B15="",NOT(ISNUMBER($D15))),"",IF(OR($B15="Total general",$B15="Total Result"),SUM(W$4:W14),+S15+U15)) | Y15: =IF(OR($B15="",NOT(ISNUMBER($D15))),"",IF(OR($B15="Total general",$B15="Total Result"),SUM(Y$4:Y14),+W15-X15)) | Z15: =IF(OR($B15="",NOT(ISNUMBER($D15))),"",IF(OR($B15="Total general",$B15="Total Result"),SUM(Z$4:Z14),+E15)) | AA15: =IF(OR($B15="",NOT(ISNUMBER($D15))),"",IF(OR($B15="Total general",$B15="Total Result"),SUM(AA$4:AA14),+Z15-W15)) | AC15: =IF(OR($B15="",NOT(ISNUMBER($D15))),"",IF(OR($B15="Total general",$B15="Total Result"),SUM(AC$4:AC14),(+M15+N15))) | AD15: =IF(OR($B15="",NOT(ISNUMBER($D15))),"",IF(OR($B15="Total general",$B15="Total Result"),SUM(AD$4:AD14),+AC15*19%)) | AE15: =IF(OR($B15="",NOT(ISNUMBER($D15))),"",IF(OR($B15="Total general",$B15="Total Result"),SUM(AE$4:AE14),+AC15-AD15)) | AF15: =IF(OR($B15="",NOT(ISNUMBER($D15))),"",IF(OR($B15="Total general",$B15="Total Result"),SUM(AF$4:AF14),+AE15-Z15))
A16: =IF(OR($B16="",OR($B16="Total general",$B16="Total Result"),NOT(ISNUMBER($D16))),"",IFERROR(INDEX(Reporte!$A$2:$A$2,MATCH($B16,Reporte!$E$2:$E$2,0))&"","")) | F16: =IF(OR($B16="",OR($B16="Total general",$B16="Total Result"),NOT(ISNUMBER($D16))),"",IFERROR(VLOOKUP($B16,Reporte!$E$2:$F$2,2,FALSE),"")) | G16: =IF(OR($B16="",OR($B16="Total general",$B16="Total Result"),NOT(ISNUMBER($D16))),"",IFERROR(VLOOKUP($B16,Reporte!$E$2:$G$2,3,FALSE),"")) | H16: =IF(OR($B16="",OR($B16="Total general",$B16="Total Result"),NOT(ISNUMBER($D16))),"",IFERROR(VLOOKUP($F16,$AI$4:$AL$4,2,FALSE),0)) | I16: =IF(OR($B16="",OR($B16="Total general",$B16="Total Result"),NOT(ISNUMBER($D16))),"",IFERROR(VLOOKUP($F16,$AI$4:$AL$4,3,FALSE),0)) | J16: =IF(OR($B16="",OR($B16="Total general",$B16="Total Result"),NOT(ISNUMBER($D16))),"",IFERROR(VLOOKUP($F16,$AI$4:$AL$4,4,FALSE),0)) | L16: =IF(OR($B16="",NOT(ISNUMBER($D16))),"",IF(OR($B16="Total general",$B16="Total Result"),SUM(L$4:L15),+D16)) | M16: =IF(OR($B16="",NOT(ISNUMBER($D16))),"",IF(OR($B16="Total general",$B16="Total Result"),SUM(M$4:M15),+L16*J16)) | N16: =IF(OR($B16="",NOT(ISNUMBER($D16))),"",IF(OR($B16="Total general",$B16="Total Result"),SUM(N$4:N15),+M16*0.1)) | R16: =IF(OR($B16="",NOT(ISNUMBER($D16))),"",IF(OR($B16="Total general",$B16="Total Result"),SUM(R$4:R15),SUM(M16:Q16)/12)) | S16: =IF(OR($B16="",NOT(ISNUMBER($D16))),"",IF(OR($B16="Total general",$B16="Total Result"),SUM(S$4:S15),SUM(M16:R16))) | U16: =IF(OR($B16="",NOT(ISNUMBER($D16))),"",IF(OR($B16="Total general",$B16="Total Result"),SUM(U$4:U15),(S16)*19%*-1)) | W16: =IF(OR($B16="",NOT(ISNUMBER($D16))),"",IF(OR($B16="Total general",$B16="Total Result"),SUM(W$4:W15),+S16+U16)) | Y16: =IF(OR($B16="",NOT(ISNUMBER($D16))),"",IF(OR($B16="Total general",$B16="Total Result"),SUM(Y$4:Y15),+W16-X16)) | Z16: =IF(OR($B16="",NOT(ISNUMBER($D16))),"",IF(OR($B16="Total general",$B16="Total Result"),SUM(Z$4:Z15),+E16)) | AA16: =IF(OR($B16="",NOT(ISNUMBER($D16))),"",IF(OR($B16="Total general",$B16="Total Result"),SUM(AA$4:AA15),+Z16-W16)) | AC16: =IF(OR($B16="",NOT(ISNUMBER($D16))),"",IF(OR($B16="Total general",$B16="Total Result"),SUM(AC$4:AC15),(+M16+N16))) | AD16: =IF(OR($B16="",NOT(ISNUMBER($D16))),"",IF(OR($B16="Total general",$B16="Total Result"),SUM(AD$4:AD15),+AC16*19%)) | AE16: =IF(OR($B16="",NOT(ISNUMBER($D16))),"",IF(OR($B16="Total general",$B16="Total Result"),SUM(AE$4:AE15),+AC16-AD16)) | AF16: =IF(OR($B16="",NOT(ISNUMBER($D16))),"",IF(OR($B16="Total general",$B16="Total Result"),SUM(AF$4:AF15),+AE16-Z16))
A17: =IF(OR($B17="",OR($B17="Total general",$B17="Total Result"),NOT(ISNUMBER($D17))),"",IFERROR(INDEX(Reporte!$A$2:$A$2,MATCH($B17,Reporte!$E$2:$E$2,0))&"","")) | F17: =IF(OR($B17="",OR($B17="Total general",$B17="Total Result"),NOT(ISNUMBER($D17))),"",IFERROR(VLOOKUP($B17,Reporte!$E$2:$F$2,2,FALSE),"")) | G17: =IF(OR($B17="",OR($B17="Total general",$B17="Total Result"),NOT(ISNUMBER($D17))),"",IFERROR(VLOOKUP($B17,Reporte!$E$2:$G$2,3,FALSE),"")) | H17: =IF(OR($B17="",OR($B17="Total general",$B17="Total Result"),NOT(ISNUMBER($D17))),"",IFERROR(VLOOKUP($F17,$AI$4:$AL$4,2,FALSE),0)) | I17: =IF(OR($B17="",OR($B17="Total general",$B17="Total Result"),NOT(ISNUMBER($D17))),"",IFERROR(VLOOKUP($F17,$AI$4:$AL$4,3,FALSE),0)) | J17: =IF(OR($B17="",OR($B17="Total general",$B17="Total Result"),NOT(ISNUMBER($D17))),"",IFERROR(VLOOKUP($F17,$AI$4:$AL$4,4,FALSE),0)) | L17: =IF(OR($B17="",NOT(ISNUMBER($D17))),"",IF(OR($B17="Total general",$B17="Total Result"),SUM(L$4:L16),+D17)) | M17: =IF(OR($B17="",NOT(ISNUMBER($D17))),"",IF(OR($B17="Total general",$B17="Total Result"),SUM(M$4:M16),+L17*J17)) | N17: =IF(OR($B17="",NOT(ISNUMBER($D17))),"",IF(OR($B17="Total general",$B17="Total Result"),SUM(N$4:N16),+M17*0.1)) | R17: =IF(OR($B17="",NOT(ISNUMBER($D17))),"",IF(OR($B17="Total general",$B17="Total Result"),SUM(R$4:R16),SUM(M17:Q17)/12)) | S17: =IF(OR($B17="",NOT(ISNUMBER($D17))),"",IF(OR($B17="Total general",$B17="Total Result"),SUM(S$4:S16),SUM(M17:R17))) | U17: =IF(OR($B17="",NOT(ISNUMBER($D17))),"",IF(OR($B17="Total general",$B17="Total Result"),SUM(U$4:U16),(S17)*19%*-1)) | W17: =IF(OR($B17="",NOT(ISNUMBER($D17))),"",IF(OR($B17="Total general",$B17="Total Result"),SUM(W$4:W16),+S17+U17)) | Y17: =IF(OR($B17="",NOT(ISNUMBER($D17))),"",IF(OR($B17="Total general",$B17="Total Result"),SUM(Y$4:Y16),+W17-X17)) | Z17: =IF(OR($B17="",NOT(ISNUMBER($D17))),"",IF(OR($B17="Total general",$B17="Total Result"),SUM(Z$4:Z16),+E17)) | AA17: =IF(OR($B17="",NOT(ISNUMBER($D17))),"",IF(OR($B17="Total general",$B17="Total Result"),SUM(AA$4:AA16),+Z17-W17)) | AC17: =IF(OR($B17="",NOT(ISNUMBER($D17))),"",IF(OR($B17="Total general",$B17="Total Result"),SUM(AC$4:AC16),(+M17+N17))) | AD17: =IF(OR($B17="",NOT(ISNUMBER($D17))),"",IF(OR($B17="Total general",$B17="Total Result"),SUM(AD$4:AD16),+AC17*19%)) | AE17: =IF(OR($B17="",NOT(ISNUMBER($D17))),"",IF(OR($B17="Total general",$B17="Total Result"),SUM(AE$4:AE16),+AC17-AD17)) | AF17: =IF(OR($B17="",NOT(ISNUMBER($D17))),"",IF(OR($B17="Total general",$B17="Total Result"),SUM(AF$4:AF16),+AE17-Z17))
... A29: =IF(OR($B29="",OR($B29="Total general",$B29="Total Result"),NOT(ISNUMBER($D29))),"",IFERROR(INDEX(Reporte!$A$2:$A$2,MATCH($B29,Reporte!$E$2:$E$2,0))&"","")) | F29: =IF(OR($B29="",OR($B29="Total general",$B29="Total Result"),NOT(ISNUMBER($D29))),"",IFERROR(VLOOKUP($B29,Reporte!$E$2:$F$2,2,FALSE),"")) | G29: =IF(OR($B29="",OR($B29="Total general",$B29="Total Result"),NOT(ISNUMBER($D29))),"",IFERROR(VLOOKUP($B29,Reporte!$E$2:$G$2,3,FALSE),"")) | H29: =IF(OR($B29="",OR($B29="Total general",$B29="Total Result"),NOT(ISNUMBER($D29))),"",IFERROR(VLOOKUP($F29,$AI$4:$AL$4,2,FALSE),0)) | I29: =IF(OR($B29="",OR($B29="Total general",$B29="Total Result"),NOT(ISNUMBER($D29))),"",IFERROR(VLOOKUP($F29,$AI$4:$AL$4,3,FALSE),0)) | J29: =IF(OR($B29="",OR($B29="Total general",$B29="Total Result"),NOT(ISNUMBER($D29))),"",IFERROR(VLOOKUP($F29,$AI$4:$AL$4,4,FALSE),0)) | L29: =IF(OR($B29="",NOT(ISNUMBER($D29))),"",IF(OR($B29="Total general",$B29="Total Result"),SUM(L$4:L28),+D29)) | M29: =IF(OR($B29="",NOT(ISNUMBER($D29))),"",IF(OR($B29="Total general",$B29="Total Result"),SUM(M$4:M28),+L29*J29)) | N29: =IF(OR($B29="",NOT(ISNUMBER($D29))),"",IF(OR($B29="Total general",$B29="Total Result"),SUM(N$4:N28),+M29*0.1)) | R29: =IF(OR($B29="",NOT(ISNUMBER($D29))),"",IF(OR($B29="Total general",$B29="Total Result"),SUM(R$4:R28),SUM(M29:Q29)/12)) | S29: =IF(OR($B29="",NOT(ISNUMBER($D29))),"",IF(OR($B29="Total general",$B29="Total Result"),SUM(S$4:S28),SUM(M29:R29))) | U29: =IF(OR($B29="",NOT(ISNUMBER($D29))),"",IF(OR($B29="Total general",$B29="Total Result"),SUM(U$4:U28),(S29)*19%*-1)) | W29: =IF(OR($B29="",NOT(ISNUMBER($D29))),"",IF(OR($B29="Total general",$B29="Total Result"),SUM(W$4:W28),+S29+U29)) | Y29: =IF(OR($B29="",NOT(ISNUMBER($D29))),"",IF(OR($B29="Total general",$B29="Total Result"),SUM(Y$4:Y28),+W29-X29)) | Z29: =IF(OR($B29="",NOT(ISNUMBER($D29))),"",IF(OR($B29="Total general",$B29="Total Result"),SUM(Z$4:Z28),+E29)) | AA29: =IF(OR($B29="",NOT(ISNUMBER($D29))),"",IF(OR($B29="Total general",$B29="Total Result"),SUM(AA$4:AA28),+Z29-W29)) | AC29: =IF(OR($B29="",NOT(ISNUMBER($D29))),"",IF(OR($B29="Total general",$B29="Total Result"),SUM(AC$4:AC28),(+M29+N29))) | AD29: =IF(OR($B29="",NOT(ISNUMBER($D29))),"",IF(OR($B29="Total general",$B29="Total Result"),SUM(AD$4:AD28),+AC29*19%)) | AE29: =IF(OR($B29="",NOT(ISNUMBER($D29))),"",IF(OR($B29="Total general",$B29="Total Result"),SUM(AE$4:AE28),+AC29-AD29)) | AF29: =IF(OR($B29="",NOT(ISNUMBER($D29))),"",IF(OR($B29="Total general",$B29="Total Result"),SUM(AF$4:AF28),+AE29-Z29))
